Workbook

Sheet Cover
A1: x-change — Reward & Token Calculator
A3: Policy source: docs/policy-core-v0.md | Code: src/xchange/domain.py | Version: 1.0
A4: This model implements the x-change v0 epistemic token lifecycle in full. It covers: (1) rarity scoring via the compute_rarity_score() formula with configurable weights, (2) all five InsightTier classifications and their backward-compatible integer amounts, (3) the six-state reward lifecycle and valid transition paths, (4) a live 15-token portfolio log with formula-driven rarity scores, (5) layered exchange constraint evaluation (safety → ethics → economic), and (6) a portfolio summary dashboard. All yellow cells are editable inputs (blue text). All black text cells are formulas — do not hardcode them.
A6: Navigation
A7: Sheet | B7: Purpose | C7: Key Inputs | D7: Key Outputs
A8: Assumptions | B8: All configurable parameters — edit here first | C8: Rarity weights, tier table, constraint config, blocked / irreversible key lists | D8: Named inputs referenced by all other sheets
A9: Rarity_Calc | B9: Single-token rarity score calculator | C9: Insight tier, inferential richness, trend position | D9: Rarity score (0-1), component breakdown, tier amount
A10: Tier_Ref | B10: InsightTier reference table | C10: None (reference only) | D10: Tier order, rarity weight, amount, description
A11: Lifecycle | B11: Reward state machine and valid transitions | C11: Current state, evidence type, policy flags | D11: Valid next states, outcome state, notes
A12: Token_Log | B12: Portfolio of 15 sample issued tokens | C12: Per-token: tier, base_bank_depth, inferential richness, trend position | D12: Rarity score, amount, portfolio-level stats
A13: Exchange_Eval | B13: Layered exchange constraint evaluator | C13: Requested scope (up to 10 key-value pairs), explicit approval flag | D13: Per-layer pass/block/strip result, final approved scope, overall decision
A14: Summary | B14: Portfolio dashboard — aggregate view | C14: Driven by Token_Log (no manual input) | D14: Tokens by tier, avg rarity by tier, total amount, rarity bands
A17: Model Metadata
A18: Policy Version | B18: policy-core-v0
A19: Model Version | B19: 1.0
A20: Domain Code | B20: src/xchange/domain.py
A21: Rarity Formula | B21: 0.4×(1−trend_position) + 0.4×inferential_richness + 0.2×tier_weight
A22: Token Amounts | B22: surface=1, pattern=2, structural=3, causal=4, theoretical=5
A23: Constraint Layers | B23: 1. Safety/Security (hard gate) 2. Ethics/Irreversibility 3. Economic Stability
A24: Build Date | B24: 2026-05-07

Sheet Assumptions
A1: A. Rarity Score Weights
A2: Parameter | B2: Value | C2: Validation | D2: Source
A3: Emergence Weight (w_emergence) | B3: 0.4 | D3: Source: domain.py:compute_rarity_score, line 111
A4: Inferential Richness Weight (w_inferential) | B4: 0.4
A5: Epistemic Tier Weight (w_tier) | B5: 0.2
A6: Weight Sum (must equal 100.0%) | B6: =SUM(B3:B5) | C6: =IF(ABS(B6-1)<0.0001,"✓ OK","✗ ERROR — weights must sum to 1.0")
A8: B. Insight Tier Reference Table
A9: Tier (text key) | B9: Rarity Weight | C9: Amount (int) | D9: Description | E9: Tier Order
A10: surface | B10: 0 | C10: 1 | D10: Fact recall, basic recognition | E10: 1
A11: pattern | B11: 0.25 | C11: 2 | D11: Cross-domain pattern recognition | E11: 2
A12: structural | B12: 0.5 | C12: 3 | D12: Structural understanding, system maps | E12: 3
A13: causal | B13: 0.75 | C13: 4 | D13: Causal chain modelling, root cause | E13: 4
A14: theoretical | B14: 1 | C14: 5 | D14: Novel synthesis, theory building | E14: 5
D15: Source: domain.py:InsightTier + _TIER_AMOUNTS, lines 48-79
A17: C. Economic Constraint Defaults
A18: Parameter | B18: Value | D18: Source
A19: Max Token Amount (cap on token_amount scope key) | B19: 10 | D19: Source: domain.py:ConstraintConfig.max_token_amount
A20: Max Scope Items (max keys approved) | B20: 5 | D20: Source: domain.py:ConstraintConfig.max_scope_items
A21: Require Explicit Irreversible Approval (TRUE/FALSE) | B21: TRUE | D21: Source: domain.py:ConstraintConfig.require_explicit_irreversible_approval
A23: D. Blocked Scope Keys (Safety/Security — Hard Gate)
A24: Scope Key | B24: Reason for Block
A25: admin_override | B25: Bypasses policy — never approvable
A26: raw_db_write | B26: Direct database mutation; unsafe
A27: delete_reward | B27: Irreversible data destruction
A28: bypass_constraints | B28: Self-referential safety bypass
A29: payment_redirect | B29: Financial fraud vector
B30: (add custom blocked key here)
B31: (add custom blocked key here)
B32: (add custom blocked key here)
A34: E. Irreversible Scope Keys (Ethics/Irreversibility Layer)
A35: Scope Key | B35: Reason
A36: finalize_contract | B36: Contract closure cannot be undone
A37: archive_student | B37: Student record archival is permanent
A38: issue_final_token | B38: Token issuance is immutable
A39: submit_stripe_charge | B39: Payment charges non-reversible automatically
B40: (add custom irreversible key here)
B41: (add custom irreversible key here)
B42: (add custom irreversible key here)

Sheet Rarity_Calc
A1: Single-Token Rarity Score Calculator
A2: Enter inputs below (yellow cells). Scores are computed by formulas referencing Assumptions!
A4: Inputs
A5: Field | B5: Value | C5: Allowed Range | D5: Notes
A6: insight_tier | B6: causal | C6: surface / pattern / structural / causal / theoretical | D6: Choose from tier list: surface / pattern / structural / causal / theoretical
A7: base_bank_depth | B7: 75 | C7: 0 – 100 (int) | D7: Knowledge-base depth score (informational — not used in rarity formula)
A8: inferential_richness | B8: 0.82 | C8: 0.00 – 1.00 | D8: Depth of reasoning chain (0 = shallow, 1 = maximal depth)
A9: trend_position | B9: 0.35 | C9: 0.00 – 1.00 | D9: 0 = emerging edge (rare), 1 = well-established (common)
A10: issuance_trigger | B10: causal_chain_identified | C10: free text | D10: Cognitive event that triggered this issuance
A13: Computed Outputs
A14: Output | B14: Value | C14: Formula | D14: Notes
A15: tier_rarity_weight | B15: =IFERROR(VLOOKUP(B6,Assumptions!$A$10:$B$14,2,FALSE),"N/A") | C15: =VLOOKUP(B6, Assumptions!A10:B14, 2, FALSE) | D15: Tier-specific weight from Assumptions table
A16: tier_amount | B16: =IFERROR(VLOOKUP(B6,Assumptions!$A$10:$C$14,3,FALSE),"N/A") | C16: =VLOOKUP(B6, Assumptions!A10:C14, 3, FALSE) | D16: Backward-compatible integer amount for this tier
A17: emergence_component | B17: =IFERROR(Assumptions!$B$3*(1-B9),"N/A") | C17: =w_emergence × (1 − trend_position) | D17: 40% weight on how far from well-established edge
A18: inferential_component | B18: =IFERROR(Assumptions!$B$4*B8,"N/A") | C18: =w_inferential × inferential_richness | D18: 40% weight on depth of reasoning chain
A19: tier_component | B19: =IFERROR(Assumptions!$B$5*VLOOKUP(B6,Assumptions!$A$10:$B$14,2,FALSE),"N/A") | C19: =w_tier × tier_rarity_weight | D19: 20% weight on epistemic tier
A20: rarity_score (0.00 – 1.00) | B20: =IFERROR(MAX(0,MIN(1,B17+B18+B19)),"N/A") | C20: =MAX(0, MIN(1, emergence + inferential + tier)) | D20: Final rarity score stamped at issuance — NEVER recompute after issue
A23: Rarity Score Interpretation Guide
A24: Score Range | B24: Classification | C24: Meaning | D24: Typical Tier
A25: 0.00 – 0.25 | B25: Common | C25: Well-established knowledge, shallow reasoning | D25: surface / pattern
A26: 0.25 – 0.50 | B26: Uncommon | C26: Moderate depth, some emerging edge | D26: pattern / structural
A27: 0.50 – 0.75 | B27: Rare | C27: High inferential depth, emerging domain | D27: structural / causal
A28: 0.75 – 1.00 | B28: Very Rare | C28: Theoretical synthesis at knowledge frontier | D28: causal / theoretical

Sheet Tier_Ref
A1: Insight Tier Reference (domain.py: InsightTier, lines 48–78)
A2: Tier Key | B2: Order | C2: Amount (int) | D2: Rarity Weight | E2: Description | F2: Cognitive Demand
A3: =Assumptions!A10 | B3: =Assumptions!E10 | C3: =Assumptions!C10 | D3: =Assumptions!B10 | E3: Fact recall, basic recognition | F3: Low — retrieval and identification
A4: =Assumptions!A11 | B4: =Assumptions!E11 | C4: =Assumptions!C11 | D4: =Assumptions!B11 | E4: Cross-domain pattern recognition | F4: Moderate — synthesis across contexts
A5: =Assumptions!A12 | B5: =Assumptions!E12 | C5: =Assumptions!C12 | D5: =Assumptions!B12 | E5: Structural understanding, system maps | F5: High — system-level comprehension
A6: =Assumptions!A13 | B6: =Assumptions!E13 | C6: =Assumptions!C13 | D6: =Assumptions!B13 | E6: Causal chain modelling, root cause analysis | F6: Very High — causal inference & modelling
A7: =Assumptions!A14 | B7: =Assumptions!E14 | C7: =Assumptions!C14 | D7: =Assumptions!B14 | E7: Novel synthesis, theory building at frontier | F7: Maximal — new theory generation
A11: Rarity Formula (domain.py:compute_rarity_score)
A12: rarity_score = w_emergence × (1 − trend_position) + w_inferential × inferential_richness + w_tier × tier_rarity_weight where w_emergence=0.4, w_inferential=0.4, w_tier=0.2 (see Assumptions!B3:B5) Result clamped to [0.0, 1.0] and rounded to 4 decimal places.

Sheet Lifecycle
A1: Reward State Machine (domain.py: RewardState, lines 14–22)
A3: A. State Definitions
A4: State | B4: Outcome State | C4: Meaning
A5: drafted | B5: unknown | C5: Reward created; awaiting contract satisfaction
A6: earned | B6: unknown | C6: Contract satisfied; awaiting payment instruction
A7: payment_pending | B7: unknown | C7: Ready for payment; Stripe charge not yet confirmed
A8: payment_confirmed | B8: delivered_pending_ack | C8: Stripe confirmed; awaiting student acknowledgement
A9: student_acknowledged | B9: acknowledged | C9: Student acknowledged receipt — terminal success state
A10: review_requested | B10: review_open | C10: Review flag raised from any state — lateral transition
A13: B. Valid Transition Matrix
A14: From State | B14: → To State | C14: Trigger | D14: Policy Flag | E14: Notes
A15: drafted | B15: earned | C15: glass_session_event | D15: contract_satisfied=true | E15: domain.py:380-384
A16: earned | B16: payment_pending | C16: glass_session_event | D16: ready_for_payment=true | E16: domain.py:386-389
A17: earned | B17: payment_confirmed | C17: stripe_payment_success | D17: student_id matches | E17: domain.py:407-440
A18: payment_pending | B18: payment_confirmed | C18: stripe_payment_success | D18: student_id matches | E18: domain.py:407-440
A19: payment_confirmed | B19: student_acknowledged | C19: student_confirmation | D19: student_ack=true | E19: domain.py:364-375
A20: any | B20: review_requested | C20: any evidence | D20: request_review=true | E20: domain.py:357-362
A21: payment_confirmed | B21: payment_confirmed | C21: stripe_payment_success | D21: replay — already confirmed | E21: domain.py:419-424
A22: student_acknowledged | B22: student_acknowledged | C22: stripe_payment_success | D22: replay — already confirmed | E22: domain.py:419-424
A25: C. Evidence Types (domain.py:EvidenceType)
A26: Evidence Type | B26: Triggers Transition? | C26: Notes
A27: glass_session_event | B27: Only if policy flags set | C27: Most common; drives drafted→earned→payment_pending
A28: failure_snapshot | B28: Notes failure; no state change | C28: Recorded in notes; domain.py:391-393
A29: return_attempt | B29: No (returns None) | C29: Non-transition evidence type
A30: success_after_support | B30: No (returns None) | C30: Non-transition evidence type
A31: agent_interpretation | B31: No (returns None) | C31: Non-transition evidence type
A32: student_confirmation | B32: Yes → student_acknowledged | C32: Requires current=payment_confirmed

Sheet Token_Log
A1: Token Issuance Portfolio Log (15 sample tokens)
A2: Rarity Score and Amount columns are computed via formulas referencing Assumptions sheet. Blue-text columns are editable. Black-text columns are formula outputs.
A3: Token ID | B3: Issued At | C3: Insight Tier | D3: Base Bank Depth (0–100) | E3: Inferential Richness (0-1) | F3: Trend Position (0=emerging, 1=common) | G3: Rarity Score (formula) | H3: Amount (formula) | I3: Issuance Trigger
A4: TKN-001 | B4: 2026-04-01T09:15:00Z | C4: theoretical | D4: 88 | E4: 0.91 | F4: 0.12 | G4: =IFERROR(MAX(0,MIN(1,Assumptions!$B$3*(1-F4)+Assumptions!$B$4*E4+Assumptions!$B$5*VLOOKUP(C4,Assumptions!$A$10:$B$14,2,FALSE))),"ERR") | H4: =IFERROR(VLOOKUP(C4,Assumptions!$A$10:$C$14,3,FALSE),"ERR") | I4: novel_synthesis_identified
A5: TKN-002 | B5: 2026-04-03T14:22:00Z | C5: causal | D5: 76 | E5: 0.83 | F5: 0.28 | G5: =IFERROR(MAX(0,MIN(1,Assumptions!$B$3*(1-F5)+Assumptions!$B$4*E5+Assumptions!$B$5*VLOOKUP(C5,Assumptions!$A$10:$B$14,2,FALSE))),"ERR") | H5: =IFERROR(VLOOKUP(C5,Assumptions!$A$10:$C$14,3,FALSE),"ERR") | I5: causal_chain_identified
A6: TKN-003 | B6: 2026-04-05T11:05:00Z | C6: structural | D6: 65 | E6: 0.72 | F6: 0.45 | G6: =IFERROR(MAX(0,MIN(1,Assumptions!$B$3*(1-F6)+Assumptions!$B$4*E6+Assumptions!$B$5*VLOOKUP(C6,Assumptions!$A$10:$B$14,2,FALSE))),"ERR") | H6: =IFERROR(VLOOKUP(C6,Assumptions!$A$10:$C$14,3,FALSE),"ERR") | I6: system_map_constructed
A7: TKN-004 | B7: 2026-04-07T16:40:00Z | C7: pattern | D7: 55 | E7: 0.58 | F7: 0.62 | G7: =IFERROR(MAX(0,MIN(1,Assumptions!$B$3*(1-F7)+Assumptions!$B$4*E7+Assumptions!$B$5*VLOOKUP(C7,Assumptions!$A$10:$B$14,2,FALSE))),"ERR") | H7: =IFERROR(VLOOKUP(C7,Assumptions!$A$10:$C$14,3,FALSE),"ERR") | I7: cross_domain_link_found
A8: TKN-005 | B8: 2026-04-10T08:30:00Z | C8: surface | D8: 42 | E8: 0.22 | F8: 0.88 | G8: =IFERROR(MAX(0,MIN(1,Assumptions!$B$3*(1-F8)+Assumptions!$B$4*E8+Assumptions!$B$5*VLOOKUP(C8,Assumptions!$A$10:$B$14,2,FALSE))),"ERR") | H8: =IFERROR(VLOOKUP(C8,Assumptions!$A$10:$C$14,3,FALSE),"ERR") | I8: fact_recalled_correctly
A9: TKN-006 | B9: 2026-04-12T13:55:00Z | C9: theoretical | D9: 92 | E9: 0.95 | F9: 0.08 | G9: =IFERROR(MAX(0,MIN(1,Assumptions!$B$3*(1-F9)+Assumptions!$B$4*E9+Assumptions!$B$5*VLOOKUP(C9,Assumptions!$A$10:$B$14,2,FALSE))),"ERR") | H9: =IFERROR(VLOOKUP(C9,Assumptions!$A$10:$C$14,3,FALSE),"ERR") | I9: theory_extension_proposed
A10: TKN-007 | B10: 2026-04-14T10:10:00Z | C10: causal | D10: 81 | E10: 0.78 | F10: 0.33 | G10: =IFERROR(MAX(0,MIN(1,Assumptions!$B$3*(1-F10)+Assumptions!$B$4*E10+Assumptions!$B$5*VLOOKUP(C10,Assumptions!$A$10:$B$14,2,FALSE))),"ERR") | H10: =IFERROR(VLOOKUP(C10,Assumptions!$A$10:$C$14,3,FALSE),"ERR") | I10: root_cause_identified
A11: TKN-008 | B11: 2026-04-17T15:25:00Z | C11: structural | D11: 70 | E11: 0.68 | F11: 0.51 | G11: =IFERROR(MAX(0,MIN(1,Assumptions!$B$3*(1-F11)+Assumptions!$B$4*E11+Assumptions!$B$5*VLOOKUP(C11,Assumptions!$A$10:$B$14,2,FALSE))),"ERR") | H11: =IFERROR(VLOOKUP(C11,Assumptions!$A$10:$C$14,3,FALSE),"ERR") | I11: dependency_graph_completed
A12: TKN-009 | B12: 2026-04-20T09:45:00Z | C12: causal | D12: 73 | E12: 0.85 | F12: 0.22 | G12: =IFERROR(MAX(0,MIN(1,Assumptions!$B$3*(1-F12)+Assumptions!$B$4*E12+Assumptions!$B$5*VLOOKUP(C12,Assumptions!$A$10:$B$14,2,FALSE))),"ERR") | H12: =IFERROR(VLOOKUP(C12,Assumptions!$A$10:$C$14,3,FALSE),"ERR") | I12: mechanism_traced_to_source
A13: TKN-010 | B13: 2026-04-22T12:00:00Z | C13: pattern | D13: 60 | E13: 0.55 | F13: 0.7 | G13: =IFERROR(MAX(0,MIN(1,Assumptions!$B$3*(1-F13)+Assumptions!$B$4*E13+Assumptions!$B$5*VLOOKUP(C13,Assumptions!$A$10:$B$14,2,FALSE))),"ERR") | H13: =IFERROR(VLOOKUP(C13,Assumptions!$A$10:$C$14,3,FALSE),"ERR") | I13: recurring_pattern_named
A14: TKN-011 | B14: 2026-04-25T14:35:00Z | C14: theoretical | D14: 95 | E14: 0.93 | F14: 0.05 | G14: =IFERROR(MAX(0,MIN(1,Assumptions!$B$3*(1-F14)+Assumptions!$B$4*E14+Assumptions!$B$5*VLOOKUP(C14,Assumptions!$A$10:$B$14,2,FALSE))),"ERR") | H14: =IFERROR(VLOOKUP(C14,Assumptions!$A$10:$C$14,3,FALSE),"ERR") | I14: conceptual_bridge_built
A15: TKN-012 | B15: 2026-04-28T11:20:00Z | C15: structural | D15: 68 | E15: 0.65 | F15: 0.48 | G15: =IFERROR(MAX(0,MIN(1,Assumptions!$B$3*(1-F15)+Assumptions!$B$4*E15+Assumptions!$B$5*VLOOKUP(C15,Assumptions!$A$10:$B$14,2,FALSE))),"ERR") | H15: =IFERROR(VLOOKUP(C15,Assumptions!$A$10:$C$14,3,FALSE),"ERR") | I15: abstraction_layer_identified
... A18: TKN-015 | B18: 2026-05-05T10:50:00Z | C18: pattern | D18: 58 | E18: 0.62 | F18: 0.58 | G18: =IFERROR(MAX(0,MIN(1,Assumptions!$B$3*(1-F18)+Assumptions!$B$4*E18+Assumptions!$B$5*VLOOKUP(C18,Assumptions!$A$10:$B$14,2,FALSE))),"ERR") | H18: =IFERROR(VLOOKUP(C18,Assumptions!$A$10:$C$14,3,FALSE),"ERR") | I18: analogical_transfer_made
A21: Portfolio Statistics
A22: Metric | B22: Value | C22: Formula Note
A23: Token Count | B23: =COUNTA(A4:A18) | C23: Count all non-empty token IDs
A24: Total Amount | B24: =IFERROR(SUM(H4:H18),"ERR") | C24: Sum of all token amounts
A25: Average Rarity Score | B25: =IFERROR(AVERAGE(G4:G18),"ERR") | C25: Mean rarity across portfolio
A26: Max Rarity Score | B26: =IFERROR(MAX(G4:G18),"ERR") | C26: Highest rarity in portfolio
A27: Min Rarity Score | B27: =IFERROR(MIN(G4:G18),"ERR") | C27: Lowest rarity in portfolio
A28: Theoretical Tokens | B28: =COUNTIF(C4:C18,"theoretical") | C28: Count of theoretical-tier tokens
A29: Causal Tokens | B29: =COUNTIF(C4:C18,"causal") | C29: Count of causal-tier tokens
A30: Structural Tokens | B30: =COUNTIF(C4:C18,"structural") | C30: Count of structural-tier tokens
A31: Pattern Tokens | B31: =COUNTIF(C4:C18,"pattern") | C31: Count of pattern-tier tokens
A32: Surface Tokens | B32: =COUNTIF(C4:C18,"surface") | C32: Count of surface-tier tokens
A33: Very Rare (≥0.75) | B33: =COUNTIF(G4:G18,">="&0.75) | C33: Rarity ≥ 0.75
A34: Rare (0.50–0.74) | B34: =COUNTIFS(G4:G18,">="&0.5,G4:G18,"<"&0.75) | C34: 0.50 ≤ rarity < 0.75
A35: Uncommon (0.25–0.49) | B35: =COUNTIFS(G4:G18,">="&0.25,G4:G18,"<"&0.5) | C35: 0.25 ≤ rarity < 0.50
A36: Common (<0.25) | B36: =COUNTIF(G4:G18,"<"&0.25) | C36: Rarity < 0.25

Sheet Exchange_Eval
A1: Exchange Constraint Evaluator (domain.py:evaluate_exchange_request)
A2: Enter the requested scope (up to 10 key-value pairs) and the approval flag. The three constraint layers evaluate in order: Safety → Ethics → Economic Stability.
A4: Request Inputs
A5: Request ID | B5: REQ-001
A6: Student ID | B6: STU-042
A7: Reward ID | B7: RWD-007
A8: Explicit Irreversible Approval (TRUE/FALSE) | B8: FALSE
A10: Requested Scope (up to 10 key-value pairs)
A11: Scope Key | B11: Scope Value | C11: Type / Notes
A12: token_amount | B12: 3 | C12: int — capped by max_token_amount
A13: knowledge_domain | B13: physics | C13: str — domain of knowledge exchange
A14: session_access | B14: TRUE | C14: bool — access to session data
A15: comment | B15: earned_via_causal_chain | C15: str — human notes
A16: reward_id | B16: RWD-007 | C16: str — associated reward
A24: Layer 1: Safety / Security (Hard Gate)
A25: Scope Key | B25: In Blocked List? | C25: Layer 1 Result
A26: =A12 | B26: =IF(A12="","—",IF(COUNTIF(Assumptions!$A$25:$A$37,A12)>0,"BLOCKED","PASS"))
A27: =A13 | B27: =IF(A13="","—",IF(COUNTIF(Assumptions!$A$25:$A$37,A13)>0,"BLOCKED","PASS"))
A28: =A14 | B28: =IF(A14="","—",IF(COUNTIF(Assumptions!$A$25:$A$37,A14)>0,"BLOCKED","PASS"))
A29: =A15 | B29: =IF(A15="","—",IF(COUNTIF(Assumptions!$A$25:$A$37,A15)>0,"BLOCKED","PASS"))
A30: =A16 | B30: =IF(A16="","—",IF(COUNTIF(Assumptions!$A$25:$A$37,A16)>0,"BLOCKED","PASS"))
A31: =A17 | B31: =IF(A17="","—",IF(COUNTIF(Assumptions!$A$25:$A$37,A17)>0,"BLOCKED","PASS"))
A32: =A18 | B32: =IF(A18="","—",IF(COUNTIF(Assumptions!$A$25:$A$37,A18)>0,"BLOCKED","PASS"))
A33: =A19 | B33: =IF(A19="","—",IF(COUNTIF(Assumptions!$A$25:$A$37,A19)>0,"BLOCKED","PASS"))
A34: =A20 | B34: =IF(A20="","—",IF(COUNTIF(Assumptions!$A$25:$A$37,A20)>0,"BLOCKED","PASS"))
A35: =A21 | B35: =IF(A21="","—",IF(COUNTIF(Assumptions!$A$25:$A$37,A21)>0,"BLOCKED","PASS"))
A37: Layer 1 Overall Decision | B37: =IF(COUNTIF(B26:B35,"BLOCKED")>0,"✗ REJECTED — blocked scope key present","✓ PASSED")
A38: Blocked Key Count | B38: =COUNTIF(B26:B35,"BLOCKED")
A40: Layer 2: Ethics / Irreversibility (Scope Narrowing)
A41: Scope Key | B41: Irreversible? | C41: Approval Flag | D41: Layer 2 Result
A42: =A12 | B42: =IF(A12="","—",IF(COUNTIF(Assumptions!$A$36:$A$47,A12)>0,"YES","NO")) | C42: =$B$8 | D42: =IF(A12="","—",IF(AND(COUNTIF(Assumptions!$A$36:$A$47,A12)>0,Assumptions!$B$21="TRUE",$B$8="FALSE"),"STRIPPED","APPROVED"))
A43: =A13 | B43: =IF(A13="","—",IF(COUNTIF(Assumptions!$A$36:$A$47,A13)>0,"YES","NO")) | C43: =$B$8 | D43: =IF(A13="","—",IF(AND(COUNTIF(Assumptions!$A$36:$A$47,A13)>0,Assumptions!$B$21="TRUE",$B$8="FALSE"),"STRIPPED","APPROVED"))
A44: =A14 | B44: =IF(A14="","—",IF(COUNTIF(Assumptions!$A$36:$A$47,A14)>0,"YES","NO")) | C44: =$B$8 | D44: =IF(A14="","—",IF(AND(COUNTIF(Assumptions!$A$36:$A$47,A14)>0,Assumptions!$B$21="TRUE",$B$8="FALSE"),"STRIPPED","APPROVED"))
A45: =A15 | B45: =IF(A15="","—",IF(COUNTIF(Assumptions!$A$36:$A$47,A15)>0,"YES","NO")) | C45: =$B$8 | D45: =IF(A15="","—",IF(AND(COUNTIF(Assumptions!$A$36:$A$47,A15)>0,Assumptions!$B$21="TRUE",$B$8="FALSE"),"STRIPPED","APPROVED"))
A46: =A16 | B46: =IF(A16="","—",IF(COUNTIF(Assumptions!$A$36:$A$47,A16)>0,"YES","NO")) | C46: =$B$8 | D46: =IF(A16="","—",IF(AND(COUNTIF(Assumptions!$A$36:$A$47,A16)>0,Assumptions!$B$21="TRUE",$B$8="FALSE"),"STRIPPED","APPROVED"))
A47: =A17 | B47: =IF(A17="","—",IF(COUNTIF(Assumptions!$A$36:$A$47,A17)>0,"YES","NO")) | C47: =$B$8 | D47: =IF(A17="","—",IF(AND(COUNTIF(Assumptions!$A$36:$A$47,A17)>0,Assumptions!$B$21="TRUE",$B$8="FALSE"),"STRIPPED","APPROVED"))
A48: =A18 | B48: =IF(A18="","—",IF(COUNTIF(Assumptions!$A$36:$A$47,A18)>0,"YES","NO")) | C48: =$B$8 | D48: =IF(A18="","—",IF(AND(COUNTIF(Assumptions!$A$36:$A$47,A18)>0,Assumptions!$B$21="TRUE",$B$8="FALSE"),"STRIPPED","APPROVED"))
A49: =A19 | B49: =IF(A19="","—",IF(COUNTIF(Assumptions!$A$36:$A$47,A19)>0,"YES","NO")) | C49: =$B$8 | D49: =IF(A19="","—",IF(AND(COUNTIF(Assumptions!$A$36:$A$47,A19)>0,Assumptions!$B$21="TRUE",$B$8="FALSE"),"STRIPPED","APPROVED"))
A50: =A20 | B50: =IF(A20="","—",IF(COUNTIF(Assumptions!$A$36:$A$47,A20)>0,"YES","NO")) | C50: =$B$8 | D50: =IF(A20="","—",IF(AND(COUNTIF(Assumptions!$A$36:$A$47,A20)>0,Assumptions!$B$21="TRUE",$B$8="FALSE"),"STRIPPED","APPROVED"))
A51: =A21 | B51: =IF(A21="","—",IF(COUNTIF(Assumptions!$A$36:$A$47,A21)>0,"YES","NO")) | C51: =$B$8 | D51: =IF(A21="","—",IF(AND(COUNTIF(Assumptions!$A$36:$A$47,A21)>0,Assumptions!$B$21="TRUE",$B$8="FALSE"),"STRIPPED","APPROVED"))
...

Sheet Summary
A1: Portfolio Summary Dashboard (draws from Token_Log)
A2: All values computed from Token_Log via formulas. No manual inputs on this sheet.
A4: A. Portfolio Overview
A5: Metric | B5: Value
A6: Total Tokens Issued | B6: =COUNTA(Token_Log!A4:A18)
A7: Total Token Amount | B7: =IFERROR(SUM(Token_Log!H4:H18),0)
A8: Average Rarity Score | B8: =IFERROR(AVERAGE(Token_Log!G4:G18),0)
A9: Median Rarity Score | B9: =IFERROR(MEDIAN(Token_Log!G4:G18),0)
A10: Max Rarity Score | B10: =IFERROR(MAX(Token_Log!G4:G18),0)
A11: Min Rarity Score | B11: =IFERROR(MIN(Token_Log!G4:G18),0)
A12: Std Dev Rarity | B12: =IFERROR(STDEV(Token_Log!G4:G18),0)
A15: B. Tokens by Tier
A16: Insight Tier | B16: Count | C16: % of Portfolio | D16: Avg Rarity | E16: Avg Amount | F16: Total Amount
A17: surface | B17: =COUNTIF(Token_Log!C4:C18,"surface") | C17: =IFERROR(B17/SUM(B17:B21),0) | D17: =IFERROR(AVERAGEIF(Token_Log!C4:C18,"surface",Token_Log!G4:G18),"-") | E17: =IFERROR(AVERAGEIF(Token_Log!C4:C18,"surface",Token_Log!H4:H18),"-") | F17: =IFERROR(SUMIF(Token_Log!C4:C18,"surface",Token_Log!H4:H18),0)
A18: pattern | B18: =COUNTIF(Token_Log!C4:C18,"pattern") | C18: =IFERROR(B18/SUM(B17:B21),0) | D18: =IFERROR(AVERAGEIF(Token_Log!C4:C18,"pattern",Token_Log!G4:G18),"-") | E18: =IFERROR(AVERAGEIF(Token_Log!C4:C18,"pattern",Token_Log!H4:H18),"-") | F18: =IFERROR(SUMIF(Token_Log!C4:C18,"pattern",Token_Log!H4:H18),0)
A19: structural | B19: =COUNTIF(Token_Log!C4:C18,"structural") | C19: =IFERROR(B19/SUM(B17:B21),0) | D19: =IFERROR(AVERAGEIF(Token_Log!C4:C18,"structural",Token_Log!G4:G18),"-") | E19: =IFERROR(AVERAGEIF(Token_Log!C4:C18,"structural",Token_Log!H4:H18),"-") | F19: =IFERROR(SUMIF(Token_Log!C4:C18,"structural",Token_Log!H4:H18),0)
A20: causal | B20: =COUNTIF(Token_Log!C4:C18,"causal") | C20: =IFERROR(B20/SUM(B17:B21),0) | D20: =IFERROR(AVERAGEIF(Token_Log!C4:C18,"causal",Token_Log!G4:G18),"-") | E20: =IFERROR(AVERAGEIF(Token_Log!C4:C18,"causal",Token_Log!H4:H18),"-") | F20: =IFERROR(SUMIF(Token_Log!C4:C18,"causal",Token_Log!H4:H18),0)
A21: theoretical | B21: =COUNTIF(Token_Log!C4:C18,"theoretical") | C21: =IFERROR(B21/SUM(B17:B21),0) | D21: =IFERROR(AVERAGEIF(Token_Log!C4:C18,"theoretical",Token_Log!G4:G18),"-") | E21: =IFERROR(AVERAGEIF(Token_Log!C4:C18,"theoretical",Token_Log!H4:H18),"-") | F21: =IFERROR(SUMIF(Token_Log!C4:C18,"theoretical",Token_Log!H4:H18),0)
A22: TOTAL | B22: =SUM(B17:B21) | C22: =SUM(C17:C21) | D22: =IFERROR(AVERAGE(Token_Log!G4:G18),"") | E22: =IFERROR(AVERAGE(Token_Log!H4:H18),"") | F22: =SUM(F17:F21)
A24: C. Rarity Band Distribution
A25: Band | B25: Score Range | C25: Count | D25: % of Portfolio | E25: Avg Amount
A26: Very Rare | B26: ≥ 0.75 | C26: =COUNTIF(Token_Log!G4:G18,">="&0.75) | D26: =IFERROR(C26/SUM(C26:C29),0) | E26: =IFERROR(AVERAGEIF(Token_Log!G4:G18,">="&0.75,Token_Log!H4:H18),"-")
A27: Rare | B27: 0.50–0.74 | C27: =COUNTIFS(Token_Log!G4:G18,">="&0.5,Token_Log!G4:G18,"<"&0.75) | D27: =IFERROR(C27/SUM(C26:C29),0) | E27: =IFERROR(AVERAGEIFS(Token_Log!H4:H18,Token_Log!G4:G18,">="&0.5,Token_Log!G4:G18,"<"&0.75),"-")
A28: Uncommon | B28: 0.25–0.49 | C28: =COUNTIFS(Token_Log!G4:G18,">="&0.25,Token_Log!G4:G18,"<"&0.5) | D28: =IFERROR(C28/SUM(C26:C29),0) | E28: =IFERROR(AVERAGEIFS(Token_Log!H4:H18,Token_Log!G4:G18,">="&0.25,Token_Log!G4:G18,"<"&0.5),"-")
A29: Common | B29: < 0.25 | C29: =COUNTIF(Token_Log!G4:G18,"<"&0.25) | D29: =IFERROR(C29/SUM(C26:C29),0) | E29: =IFERROR(AVERAGEIF(Token_Log!G4:G18,"<"&0.25,Token_Log!H4:H18),"-")
